<?xml version="1.0" ?>
<sdf version="1.4">
  <model name="medibot_medibotv4">  
   <pose>0.0 0.0 0.0 0.0 0.0 0.0</pose>

    <link name="base_footprint"/>

    <link name="base_link">

      <inertial>
        <pose>0.025297764443169172 3.0256355552437136e-17 0.18296685961651218 0 0 0</pose>
        <inertia>
          <ixx>0.501298</ixx>
          <ixy>0</ixy>
          <ixz>0.050215</ixz>
          <iyy>0.524336</iyy>
          <iyz>0</iyz>
          <izz>0.640713</izz>
        </inertia>
        <mass>12.985758</mass>
      </inertial>

      <collision name="base_collision">
        <pose>-0 0 0 0 0 0</pose>
        <geometry>
          <uri>model://medibot_common/meshes/base_link.stl</uri>
          <scale>0.001 0.001 0.001</scale>
        </geometry>
      </collision>

      <visual name="base_visual">
        <pose>-0.064 0 0 0 0 0</pose>
        <geometry>
          <mesh>
            <uri>model://medibot_common/meshes/base_link.stl</uri>
            <scale>0.001 0.001 0.001</scale>
          </mesh>
        </geometry>
      </visual>
    </link>

    <link name="imu_link">
      <sensor name="medibot_imu" type="imu">
        <always_on>true</always_on>
        <update_rate>200</update_rate>
        <imu>
          <angular_velocity>
            <x>
              <noise type="gaussian">
                <mean>0.0</mean>
                <stddev>2e-4</stddev>
              </noise>
            </x>
            <y>
              <noise type="gaussian">
                <mean>0.0</mean>
                <stddev>2e-4</stddev>
              </noise>
            </y>
            <z>
              <noise type="gaussian">
                <mean>0.0</mean>
                <stddev>2e-4</stddev>
              </noise>
            </z>
          </angular_velocity>
          <linear_acceleration>
            <x>
              <noise type="gaussian">
                <mean>0.0</mean>
                <stddev>1.7e-2</stddev>
              </noise>
            </x>
            <y>
              <noise type="gaussian">
                <mean>0.0</mean>
                <stddev>1.7e-2</stddev>
              </noise>
            </y>
            <z>
              <noise type="gaussian">
                <mean>0.0</mean>
                <stddev>1.7e-2</stddev>
              </noise>
            </z>
          </linear_acceleration>
        </imu>
        <plugin name="medibot_imu" filename="libgazebo_ros_imu_sensor.so">
          <ros>
            <!-- <namespace>/medibot</namespace> -->
            <remapping>~/out:=imu</remapping>
          </ros>
        </plugin>
      </sensor>
    </link>

    <link name="base_scan">    
      <inertial>
        <pose>1.9660910471896997e-07 3.067430088395322e-17 0.014762029367898416 0 0 0</pose>
        <inertia>
          <ixx>9e-06</ixx>
          <ixy>0.000</ixy>
          <ixz>0.000</ixz>
          <iyy>9e-06</iyy>
          <iyz>0.000</iyz>
          <izz>1e-05</izz>
        </inertia>
        <mass>0.052814160089970474</mass>
      </inertial>

      <collision name="lidar_sensor_collision">
        <pose>-0.326625 -0.0 -0.225 0 0 0</pose>
        <geometry>
          <uri>model://medibot_common/meshes/lidar.stl</uri>
        </geometry>
      </collision>

      <visual name="lidar_sensor_visual">
        <pose>-0.326625 -0.0 -0.225 0 0 0</pose>
        <geometry>
          <mesh>
            <uri>model://medibot_common/meshes/lidar.stl</uri>
            <scale>0.001 0.001 0.001</scale>
          </mesh>
        </geometry>
      </visual>

      <sensor name="hls_lfcd_lds" type="ray">
        <always_on>true</always_on>
        <visualize>true</visualize>
        <pose>-0.326625 -0.0 -0.225 0 0 0</pose>
        <update_rate>5</update_rate>
        <ray>
          <scan>
            <horizontal>
              <samples>360</samples>
              <resolution>1.000000</resolution>
              <min_angle>0.000000</min_angle>
              <max_angle>6.280000</max_angle>
            </horizontal>
          </scan>
          <range>
            <min>0.120000</min>
            <max>3.5</max>
            <resolution>0.015000</resolution>
          </range>
          <noise>
            <type>gaussian</type>
            <mean>0.0</mean>
            <stddev>0.01</stddev>
          </noise>
        </ray>
        <plugin name="medibot_laserscan" filename="libgazebo_ros_ray_sensor.so">
          <ros>
            <!-- <namespace>/medibot</namespace> -->
            <remapping>~/out:=scan</remapping>
          </ros>
          <output_type>sensor_msgs/LaserScan</output_type>
          <frame_name>base_scan</frame_name>
        </plugin>
      </sensor>
    </link>

    <link name="left_wheel">
      <inertial>
        <pose>7.953816428402094e-09 -0.030000265793469483 4.539531719971457e-08 0 0 0</pose>
        <inertia>
          <ixx>0.021472</ixx>
          <ixy>-0.0</ixy>
          <ixz>0.0</ixz>
          <iyy>0.041643</iyy>
          <iyz>-0.0</iyz>
          <izz>0.021472</izz>
        </inertia>
        <mass>2.266879326854612</mass>
      </inertial>

      <collision name="left_wheel_collision">
        <pose>0.0175 -0.279 -0.16 0 0 0</pose>
        <geometry>
          <uri>model://medibot_common/meshes/left_wheel.stl</uri>
          <scale>0.001 0.001 0.001</scale>
        </geometry>
        <surface>
          <friction>
            <ode>
              <mu>100000.0</mu>
              <mu2>100000.0</mu2>
              <fdir1>0 0 0</fdir1>
              <slip1>0.0</slip1>
              <slip2>0.0</slip2>
            </ode>
          </friction>
          <contact>
            <ode>
              <soft_cfm>0</soft_cfm>
              <soft_erp>0.2</soft_erp>
              <kp>1e+5</kp>
              <kd>1</kd>
              <max_vel>0.01</max_vel>
              <min_depth>0.001</min_depth>
            </ode>
          </contact>
        </surface>
      </collision>

      <visual name="left_wheel_visual">
        <pose>0.0175 -0.279 -0.16 0 0 0</pose>
        <geometry>
          <mesh>
            <uri>model://medibot_common/meshes/left_wheel.stl</uri>
            <scale>0.001 0.001 0.001</scale>
          </mesh>
        </geometry>
      </visual>

    </link>
    <link name="right_wheel">

      <inertial>
        <pose>7.952848390252454e-09 0.030000265792822806 -4.540530937346965e-08 0 0 0</pose>
        <inertia>
          <ixx>0.021472</ixx>
          <ixy>0.0</ixy>
          <ixz>-0.0</ixz>
          <iyy>0.041643</iyy>
          <iyz>-0.0</iyz>
          <izz>0.021472</izz>
        </inertia>
        <mass>2.266879326854595</mass>
      </inertial>

      <collision name="right_wheel_collision">
        <pose>0.0175 0.279 -0.16 0 0 0</pose>
        <geometry>
          <uri>model://medibot_common/meshes/right_wheel.stl</uri>
          <scale>0.001 0.001 0.001</scale>
        </geometry>
         <surface>
          <!-- This friction pamareter don't contain reliable data!! -->
          <friction>
            <ode>
              <mu>100000.0</mu>
              <mu2>100000.0</mu2>
              <fdir1>0 0 0</fdir1>
              <slip1>0.0</slip1>
              <slip2>0.0</slip2>
            </ode>
          </friction>
          <contact>
            <ode>
              <soft_cfm>0</soft_cfm>
              <soft_erp>0.2</soft_erp>
              <kp>1e+5</kp>
              <kd>1</kd>
              <max_vel>0.01</max_vel>
              <min_depth>0.001</min_depth>
            </ode>
          </contact>
        </surface>
      </collision>

      <visual name="right_wheel_visual">
        <pose>0.0175 0.279 -0.16 0 0 0</pose>
        <geometry>
          <mesh>
            <uri>model://medibot_common/meshes/right_wheel.stl</uri>
            <scale>0.001 0.001 0.001</scale>
          </mesh>
        </geometry>
      </visual>

    </link>
    <link name="left_motor">
      <inertial>
        <pose>0.016444563411155556 0.06191343975327798 -0.056741856887104675 0 0 0</pose>
        <inertia>
          <ixx>0.057727</ixx>
          <ixy>-0.012462</ixy>
          <ixz>-0.001235</ixz>
          <iyy>0.065718</iyy>
          <iyz>-0.001816</iyz>
          <izz>0.065303</izz>
        </inertia>
        <mass>14.646460109710683</mass>
      </inertial>

      <collision name="left_motor_collision">
        <pose>0.0535 -0.1535 -0.2145 0 0 0</pose>
        <geometry>
          <uri>model://medibot_common/meshes/left_motor.stl</uri>
          <scale>0.001 0.001 0.001</scale>
        </geometry>
      </collision>

      <visual name="left_motor_visual">
        <pose>0.0535 -0.1535 -0.2145 0 0 0</pose>
        <geometry>
          <mesh>
            <uri>model://medibot_common/meshes/left_motor.stl</uri>
            <scale>0.001 0.001 0.001</scale>
          </mesh>
        </geometry>
      </visual>
    </link>

    <link name="right_motor">

      <inertial>
        <pose>0.016260474645192965 -0.06154741876400091 -0.05676908795148311 0 0 0</pose>
        <inertia>
          <ixx>0.057597</ixx>
          <ixy>0.012516</ixy>
          <ixz>-0.00123</ixz>
          <iyy>0.065274</iyy>
          <iyz>0.001804</iyz>
          <izz>0.065194</izz>
        </inertia>
        <mass>14.61528122194152</mass>
      </inertial>

      <collision name="right_motor_collision">
        <pose>0.0535 0.1535 -0.2145 0 0 0</pose>
        <geometry>
          <uri>model://medibot_common/meshes/right_motor.stl</uri>
          <scale>0.001 0.001 0.001</scale>
        </geometry>
      </collision>

      <visual name="right_motor_visual">
        <pose>0.0535 0.1535 -0.2145 0 0 0</pose>
        <geometry>
          <mesh>
            <uri>model://medibot_common/meshes/right_motor.stl</uri>
            <scale>0.001 0.001 0.001</scale>
          </mesh>
        </geometry>
      </visual>
    </link>

    <link name="bottom_panel">

      <inertial>
        <pose>0.023521505376344086 0.195 0.0025000000000000022 0 0 0</pose>
        <inertia>
          <ixx>0.01116</ixx>
          <ixy>0.0</ixy>
          <ixz>-0.0</ixz>
          <iyy>0.017329</iyy>
          <iyz>0.0</iyz>
          <izz>0.028485</izz>
        </inertia>
        <mass>0.994356</mass>
      </inertial>

      <collision name="bottom_panel_collision">
        <pose>-0.0 0.195 -0.06 0 0 0</pose>
        <geometry>
          <uri>model://medibot_common/meshes/bottom_panel.stl</uri>
          <scale>0.001 0.001 0.001</scale>
        </geometry>
      </collision>

      <visual name="bottom_panel_visual">
        <pose>-0.0 0.195 -0.06 0 0 0</pose>
        <geometry>
          <mesh>
            <uri>model://medibot_common/meshes/bottom_panel.stl</uri>
            <scale>0.001 0.001 0.001</scale>
          </mesh>
        </geometry>
      </visual>

    </link>
    <link name="circuit_panel">
      <inertial>
        <pose>0.11000000000000001 0.0 0.0025000000000000022 0 0 0</pose>
        <inertia>
          <ixx>0.006461</ixx>
          <ixy>0.0</ixy>
          <ixz>0.0</ixz>
          <iyy>0.002057</iyy>
          <iyz>0.0</iyz>
          <izz>0.008515</izz>
        </inertia>
        <mass>0.509652</mass>
      </inertial>

      <collision name="circuit_panel_collision">
        <pose>0.2 -0.0 -0.35 0 0 0</pose>
        <geometry>
          <uri>model://medibot_common/meshes/circuit_panel.stl</uri>
          <scale>0.001 0.001 0.001</scale>
        </geometry>
      </collision>

      <visual name="circuit_panel_visual">
        <pose>0.2 -0.0 -0.35 0 0 0</pose>
        <geometry>
          <mesh>
            <uri>model://medibot_common/meshes/circuit_panel.stl</uri>
            <scale>0.001 0.001 0.001</scale>
          </mesh>
        </geometry>
      </visual>

    </link>
    <link name="circuit_housing">

      <inertial>
        <pose>0.11586679295026386 -4.768835044584394e-17 0.11525745568764251 0 0 0</pose>
        <inertia>
          <ixx>0.370761</ixx>
          <ixy>0.0</ixy>
          <ixz>-0.018114</ixz>
          <iyy>0.314986</iyy>
          <iyz>0.0</iyz>
          <izz>0.346648</izz>
        </inertia>
        <mass>23.953970618548663</mass>
      </inertial>

      <collision name="circuit_housing_collision">
        <pose>0.2 -0.0 -0.355 0 0 0</pose>
        <geometry>
          <uri>model://medibot_common/meshes/circuit_housing.stl</uri>
          <scale>0.001 0.001 0.001</scale>
        </geometry>
      </collision>

      <visual name="circuit_housing_visual">
        <pose>0.2 -0.0 -0.355 0 0 0</pose>
        <geometry>
          <mesh>
            <uri>model://medibot_common/meshes/circuit_housing.stl</uri>
            <scale>0.001 0.001 0.001</scale>
          </mesh>
        </geometry>
      </visual>
    </link>

    <link name="stand">
      <inertial>
        <pose>-0.03 -5.005474418122885e-18 0.504332691249312 0 0 0</pose>
        <inertia>
          <ixx>0.832484</ixx>
          <ixy>0.0</ixy>
          <ixz>0.0</ixz>
          <iyy>0.832484</iyy>
          <iyz>0.0</iyz>
          <izz>0.006002</izz>
        </inertia>
        <mass>9.811799999999998</mass>
      </inertial>

      <collision name="stand_collision">
        <pose>-0.08 -0.0 -0.065 0 0 0</pose>
        <geometry>
          <uri>model://medibot_common/meshes/stand.stl</uri>
          <scale>0.001 0.001 0.001</scale>
        </geometry>
      </collision>

      <visual name="stand_visual">
        <pose>-0.08 -0.0 -0.065 0 0 0</pose>
        <geometry>
          <mesh>
            <uri>model://medibot_common/meshes/stand.stl</uri>
            <scale>0.001 0.001 0.001</scale>
          </mesh>
        </geometry>
      </visual>
    </link>

    <link name="body">

      <inertial>
        <pose>0.24442242538485656 1.3361487722796229e-15 0.22269634119543633 0 0 0</pose>
        <inertia>
          <ixx>5.513959</ixx>
          <ixy>0.0</ixy>
          <ixz>0.070146</ixz>
          <iyy>4.755007</iyy>
          <iyz>0.0</iyz>
          <izz>7.74447</izz>
        </inertia>
        <mass>78.65436391485291</mass>
      </inertial>

      <collision name="body_collision">
        <pose>0.2 -0.0 -0.03 0 0 0</pose>
        <geometry>
          <uri>model://medibot_common/meshes/body.stl</uri>
          <scale>0.001 0.001 0.001</scale>
        </geometry>
      </collision>

      <visual name="body_visual">
        <pose>0.2 -0.0 -0.03 0 0 0</pose>
        <geometry>
          <mesh>
            <uri>model://medibot_common/meshes/body.stl</uri>
            <scale>0.001 0.001 0.001</scale>
          </mesh>
        </geometry>
      </visual>
    </link>

    <link name="top_panel">

      <inertial>
        <pose>-0.3000421262648231 1.8731188253870525e-07 0.0156616040392335 0 0 0</pose>
        <inertia>
          <ixx>0.9738</ixx>
          <ixy>1e-06</ixy>
          <ixz>0.00562</ixz>
          <iyy>0.652206</iyy>
          <iyz>0.0</iyz>
          <izz>1.61362</izz>
        </inertia>
        <mass>32.135656783601455</mass>
      </inertial>

      <collision name="top_panel_collision">
        <pose>-0.366625 0.0 -0.47 0 0 0</pose>
        <geometry>
          <uri>model://medibot_common/meshes/top_panel.stl</uri>
          <scale>0.001 0.001 0.001</scale>
        </geometry>
        <surface>
          <contact>
            <ode>
              <soft_cfm>0</soft_cfm>
              <soft_erp>0.2</soft_erp>
              <kp>1e+5</kp>
              <kd>1</kd>
              <max_vel>0.01</max_vel>
              <min_depth>0.001</min_depth>
            </ode>
          </contact>
        </surface>
      </collision>

      <visual name="top_panel_visual">
        <pose>-0.366625 0.0 -0.47 0 0 0</pose>
        <geometry>
          <mesh>
            <uri>model://medibot_common/meshes/top_panel.stl</uri>
            <scale>0.001 0.001 0.001</scale>
          </mesh>
        </geometry>
        
      </visual>

    </link>

    <link name="realsense_housing">

      <inertial>
        <pose>-0.07373817098769747 7.951322418324285e-17 0.04233590361579864 0 0 0</pose>
        <inertia>
          <ixx>0.003621</ixx>
          <ixy>-0.0</ixy>
          <ixz>7.1e-05</ixz>
          <iyy>0.001194</iyy>
          <iyz>-0.0</iyz>
          <izz>0.003857</izz>
        </inertia>
        <mass>0.4849831679105662</mass>
      </inertial>

      <collision name="realsense_housing_collision">
        <pose>-0.171141 -0.0 -0.52 0 0 0</pose>
        <geometry>
          <uri>model://medibot_common/meshes/realsense_housing.stl</uri>
          <scale>0.001 0.001 0.001</scale>
        </geometry>
        <surface>
          <contact>
            <ode>
              <soft_cfm>0</soft_cfm>
              <soft_erp>0.2</soft_erp>
              <kp>1e+5</kp>
              <kd>1</kd>
              <max_vel>0.01</max_vel>
              <min_depth>0.001</min_depth>
            </ode>
          </contact>
        </surface>
      </collision>

      <visual name="realsense_housing_visual">
        <pose>-0.171141 -0.0 -0.52 0 0 0</pose>
        <geometry>
          <mesh>
            <uri>model://medibot_common/meshes/realsense_housing.stl</uri>
            <scale>0.001 0.001 0.001</scale>
          </mesh>
        </geometry>
      </visual>

    </link>



    <link name="left_realsense">

      <inertial>
        <pose>0.00266926405942991 0.0011190896800006983 0.0 0 0 0</pose>
        <inertia>
          <ixx>4.8e-05</ixx>
          <ixy>1.9e-05</ixy>
          <ixz>0.0</ixz>
          <iyy>1.1e-05</iyy>
          <iyz>0.0</iyz>
          <izz>5.3e-05</izz>
        </inertia>
        <mass>0.04923710067597887</mass>
      </inertial>

      <collision name="left_realsense_collision">
        <pose>-0.147314 -0.059696 -0.56 0 0 0</pose>
        <geometry>
          <uri>model://medibot_common/meshes/left_realsense.stl</uri>
          <scale>0.001 0.001 0.001</scale>
        </geometry>
      </collision>

      <visual name="left_realsense_visual">
        <pose>-0.147314 -0.059696 -0.56 0 0 0</pose>
        <geometry>
          <mesh>
            <uri>model://medibot_common/meshes/left_realsense.stl</uri>
            <scale>0.001 0.001 0.001</scale>
          </mesh>
        </geometry>
      </visual>

    </link>

    <link name="right_realsense">

      <inertial>
        <pose>0.0026692640594299655 -0.0011190896800007816 5.551115123125783e-16 0 0 0</pose>
        <inertia>
          <ixx>4.8e-05</ixx>
          <ixy>-1.9e-05</ixy>
          <ixz>0.0</ixz>
          <iyy>1.1e-05</iyy>
          <iyz>-0.0</iyz>
          <izz>5.3e-05</izz>
        </inertia>
        <mass>0.04923710067597842</mass>
      </inertial>

      <collision name="right_realsense_collision">
        <pose>-0.147314 0.059696 -0.56 0 0 0</pose>
        <geometry>
          <uri>model://medibot_common/meshes/right_realsense.stl</uri>
          <scale>0.001 0.001 0.001</scale>
        </geometry>
      </collision>

      <visual name="right_realsense_visual">
        <pose>-0.147314 0.059696 -0.56 0 0 0</pose>
        <geometry>
          <mesh>
            <uri>model://medibot_common/meshes/right_realsense.stl</uri>
            <scale>0.001 0.001 0.001</scale>
          </mesh>
        </geometry>
      </visual>

    </link>

         <link name="sonar">

      <inertial>
        <pose>0.024761040929337313 1.4803902564637098e-17 0.03249999999999986 0 0 0</pose>
        <inertia>
          <ixx>0.016776</ixx>
          <ixy>0.0</ixy>
          <ixz>0.0</ixz>
          <iyy>0.0062</iyy>
          <iyz>0.0</iyz>
          <izz>0.021141</izz>
        </inertia>
        <mass>2.6048925401122753</mass>
      </inertial>

      <collision name="sonar_collision">
        <pose>-0.08 -0.0 -0.69 0 0 0</pose>
        <geometry>
          <uri>model://medibot_common/meshes/sonar.stl</uri>
          <scale>0.001 0.001 0.001</scale>
        </geometry>
      </collision>

      <visual name="sonar_visual">
        <pose>-0.08 -0.0 -0.69 0 0 0</pose>
        <geometry>
          <mesh>
            <uri>model://medibot_common/meshes/sonar.stl</uri>
            <scale>0.001 0.001 0.001</scale>
          </mesh>
        </geometry>
      </visual>
    </link>

    <link name="pan_servo">

      <inertial>
        <pose>-0.0021812244512274467 -0.028563653527876792 0.05585888345427237 0 0 0</pose>
        <inertia>
          <ixx>0.022969</ixx>
          <ixy>0.000699</ixy>
          <ixz>0.000791</ixz>
          <iyy>0.022195</iyy>
          <iyz>0.000526</iyz>
          <izz>0.028495</izz>
        </inertia>
        <mass>11.218433692744027</mass>
      </inertial>

      <collision name="pan_servo_collision">
        <pose>-0.05 -0.0 -1.06 0 0 0</pose>
        <geometry>
          <uri>model://medibot_common/meshes/pan_servo.stl</uri>
          <scale>0.001 0.001 0.001</scale>
        </geometry>
      </collision>

      <visual name="pan_servo_visual">
        <pose>-0.05 -0.0 -1.06 0 0 0</pose>
        <geometry>
          <mesh>
            <uri>model://medibot_common/meshes/pan_servo.stl</uri>
            <scale>0.001 0.001 0.001</scale>
          </mesh>
        </geometry>
      </visual>
    </link>

    <link name="pan_tilt_mount">

      <inertial>
        <pose>-0.001000621165341782 0.007999999999999986 0.09809881978571133 0 0 0</pose>
        <inertia>
          <ixx>0.010238</ixx>
          <ixy>0.0</ixy>
          <ixz>0.000149</ixz>
          <iyy>0.014175</iyy>
          <iyz>-0.0</iyz>
          <izz>0.004065</izz>
        </inertia>
        <mass>3.0191586385796634</mass>
      </inertial>

      <collision name="pan_tilt_mount_collision">
        <pose>-0.05 -0.035 -1.07 0 0 0</pose>
        <geometry>
          <uri>model://medibot_common/meshes/pan_tilt_mount.stl</uri>
          <scale>0.001 0.001 0.001</scale>
        </geometry>
      </collision>

      <visual name="pan_tilt_mount_visual">
        <pose>-0.05 -0.035 -1.07 0 0 0</pose>
        <geometry>
          <mesh>
            <uri>model://medibot_common/meshes/pan_tilt_mount.stl</uri>
            <scale>0.001 0.001 0.001</scale>
          </mesh>
        </geometry>
      </visual>

    </link>

        <link name="tilt_servo">

        <inertial>
            <pose>0.00024389797280190834 0.049434156703140976 -0.062402440810886306 0 0 0</pose>
            <inertia>
                <ixx>0.026619</ixx>
                <ixy>0.000174</ixy>
                <ixz>-3e-05</ixz>
                <iyy>0.032047</iyy>
                <iyz>6.9e-05</iyz>
                <izz>0.026681</izz>
            </inertia>
            <mass>12.386466361420336</mass>
        </inertial>

        <collision name="tilt_servo_collision">
            <pose>-0.05 -0.051 -1.27 0 0 0</pose>
            <geometry>
                <uri>model://medibot_common/meshes/tilt_servo.stl</uri>
                <scale>0.001 0.001 0.001</scale>
            </geometry>
        </collision>

        <visual name="tilt_servo_visual">
            <pose>-0.05 -0.051 -1.27 0 0 0</pose>
            <geometry>
                <mesh>
                    <uri>model://medibot_common/meshes/tilt_servo.stl</uri>
                    <scale>0.001 0.001 0.001</scale>
                </mesh>
            </geometry>
        </visual>
    </link>

    <link name="monitor">

        <inertial>
            <pose>0.010000010577328328 -1.1068901035776004e-16 2.407478818522435e-07 0 0 0</pose>
            <inertia>
                <ixx>0.141427</ixx>
                <ixy>0.0</ixy>
                <ixz>0.0</ixz>
                <iyy>0.105382</iyy>
                <iyz>-0.0</iyz>
                <izz>0.036295</izz>
            </inertia>
            <mass>3.7546879999999994</mass>
        </inertial>

        <collision name="monitor_collision">
            <pose>-0.1475 0.0 -1.217519 0 0 0</pose>
            <geometry>
                <uri>model://medibot_common/meshes/monitor.stl</uri>
                <scale>0.001 0.001 0.001</scale>
            </geometry>
        </collision>

        <visual name="monitor_visual">
            <pose>-0.1475 0.0 -1.217519 0 0 0</pose>
            <geometry>
                <mesh>
                    <uri>model://medibot_common/meshes/monitor.stl</uri>
                    <scale>0.001 0.001 0.001</scale>
                </mesh>
            </geometry>
        </visual>
    </link>

    <link name="camera_housing">

        <inertial>
            <pose>0.0074877939399487226 1.823328231606211e-17 -0.009962494459304638 0 0 0</pose>
            <inertia>
                <ixx>0.000178</ixx>
                <ixy>-0.0</ixy>
                <ixz>-4.9e-05</ixz>
                <iyy>0.000123</iyy>
                <iyz>0.0</iyz>
                <izz>0.000169</izz>
            </inertia>
            <mass>0.19827705055401032</mass>
        </inertial>

        <collision name="camera_housing_collision">
            <pose>-0.192857 -0.0 -1.561149 0 0 0</pose>
            <geometry>
                <uri>model://medibot_common/meshes/camera_housing.stl</uri>
                <scale>0.001 0.001 0.001</scale>
            </geometry>
        </collision>

        <visual name="camera_housing_visual">
            <pose>-0.192857 -0.0 -1.561149 0 0 0</pose>
            <geometry>
                <mesh>
                    <uri>model://medibot_common/meshes/camera_housing.stl</uri>
                    <scale>0.001 0.001 0.001</scale>
                </mesh>
            </geometry>
        </visual>

    </link>

    <link name="camera">

        <inertial>
            <pose>0.0074999594047501505 -2.958887009148109e-07 -0.005624916158602389 0 0 0</pose>
            <inertia>
                <ixx>1e-05</ixx>
                <ixy>-0.0</ixy>
                <ixz>-2e-06</ixz>
                <iyy>8e-06</iyy>
                <iyz>-0.0</iyz>
                <izz>9e-06</izz>
            </inertia>
            <mass>0.04663301595172273</mass>
        </inertial>

        <collision name="camera_collision">
            <pose>-0.217785 -8e-06 -1.549013 0 0 0</pose>
            <geometry>
                <uri>model://medibot_common/meshes/camera.stl</uri>
                <scale>0.001 0.001 0.001</scale>
            </geometry>
        </collision>

        <visual name="camera_visual">
            <pose>-0.217785 -8e-06 -1.549013 0 0 0</pose>
            <geometry>
                <mesh>
                    <uri>model://medibot_common/meshes/camera.stl</uri>
                    <scale>0.001 0.001 0.001</scale>
                </mesh>
            </geometry>
        </visual>
      <sensor name="camera" type="camera">
        <always_on>true</always_on>
        <visualize>true</visualize>
        <update_rate>30</update_rate>
        <camera name="intel_realsense_r200">
          <horizontal_fov>1.02974</horizontal_fov>
          <image>
            <width>1920</width>
            <height>1080</height>
            <format>R8G8B8</format>
          </image>
          <clip>
            <near>0.02</near>
            <far>300</far>
          </clip>
          <noise>
            <type>gaussian</type>
            <!-- Noise is sampled independently per pixel on each frame.
                  That pixel's noise value is added to each of its color
                  channels, which at that point lie in the range [0,1]. -->
            <mean>0.0</mean>
            <stddev>0.007</stddev>
          </noise>
        </camera>
          <plugin name="camera_driver" filename="libgazebo_ros_camera.so">
            <ros>
              <!-- <namespace>test_cam</namespace> -->
              <!-- <remapping>image_raw:=image_demo</remapping> -->
              <!-- <remapping>camera_info:=camera_info_demo</remapping> -->
            </ros>
            <!-- camera_name>omit so it defaults to sensor name</camera_name-->
            <!-- frame_name>omit so it defaults to link name</frameName-->
            <!-- <hack_baseline>0.07</hack_baseline> -->
          </plugin>
      </sensor>
    </link>

     <link name="caster">
        <inertial>
            <pose> 0.0 -1.0052123437711852e-17 -0.01125000000000002 0 0 0 </pose>
            <mass value="0.4439070419522379"/>
            <inertia ixx="0.000104" ixy="0.0" ixz="-0.0" iyy="0.000104" iyz="-0.0" izz="0.00016"/>
        </inertial>
        <visual>
            <pose> -0.2885 -0.0 -0.03 0 0 0 </pose>
            <geometry>
                <mesh filename="package://medibotv4_description/meshes/caster.stl" scale="0.001 0.001 0.001"/>
            </geometry>
            <material name="black"/>
        </visual>
        <collision>
            <pose> -0.2885 -0.0 -0.03 0 0 0 </pose>
            <geometry>
                <mesh filename="package://medibotv4_description/meshes/caster.stl" scale="0.001 0.001 0.001"/>
            </geometry>
        </collision>
     </link>


    <joint name="base_joint" type="fixed">
      <parent>base_footprint</parent>
      <child>base_link</child>
      <pose>0.0 0.0 0.010 0 0 0</pose>
    </joint>

   <joint name="left_motor_joint" type="fixed">
      <pose> -0.0535 0.1535 0.2145 0 0 0 </pose>
      <parent link="base_link"/>
      <child link="left_motor"/>
   </joint>

   <joint name="right_motor_joint" type="fixed">
      <pose> -0.0535 -0.1535 0.2145 0 0 0 </pose>
      <parent link="base_link"/>
      <child link="right_motor"/>
   </joint>

   <joint name="wheel_left_joint" type="continuous">
      <pose> 0.036 0.1255 -0.0545 0 0 0 </pose>
      <parent link="left_motor"/>
      <child link="left_wheel"/>
      <axis>
        <xyz>0.0 1.0 0.0</xyz>
      </axis>
   </joint>

   <joint name="wheel_right_joint" type="continuous">
      <pose> 0.036 -0.1255 -0.0545 0 0 0 </pose>
      <parent link="right_motor"/>
      <child link="right_wheel"/>
      <axis>
      <xyz>-0.0 1.0 0.0"</xyz>
      </axis>
   </joint>

   <joint name="bottom_panel_joint" type="fixed">
      <pose> 0.0 -0.195 0.06 0 0 0 </pose>
      <parent link="base_link"/>
      <child link="bottom_panel"/>
   </joint>

   <joint name="circuit_panel_joint" type="fixed">
      <pose> -0.2 0.0 0.35 0 0 0 </pose>
      <parent link="base_link"/>
      <child link="circuit_panel"/>
   </joint>

   <joint name="cicuit_housing_joint" type="fixed">
      <pose> 0.0 0.0 0.005 0 0 0 </pose>
      <parent link="circuit_panel"/>
      <child link="circuit_housing"/>
   </joint>

   <joint name="stand_joint" type="fixed">
      <pose> 0.08 0.195 0.005 0 0 0 </pose>
      <parent link="bottom_panel"/>
      <child link="stand"/>
   </joint>


    <joint name="imu_joint" type="fixed">
      <parent>base_link</parent>
      <child>imu_link</child>
      <pose>-0.032 0 0.068 0 0 0</pose>
      <axis>
        <xyz>0 0 1</xyz>
      </axis>
    </joint>    

   <joint name="body_joint" type="fixed">
      <pose> -0.2 0.0 0.03 0 0 0 </pose>
      <parent link="base_link"/>
      <child link="body"/>
   </joint>

   <joint name="lidar_joint" type="fixed">
      <pose> 0.526625 0.0 0.195 0 0 0 </pose>
      <parent link="body"/>
      <child link="lidar"/>
   </joint>

   <joint name="top_panel_joint" type="fixed">
      <pose> 0.566625 -0.0 0.44 0 0 0 </pose>
      <parent link="body"/>
      <child link="top_panel"/>
   </joint>

   <joint name="realsense_housing_joint" type="fixed">
      <pose> -0.195484 0.0 0.05 0 0 0 </pose>
      <parent link="top_panel"/>
      <child link="realsense_housing"/>
   </joint>

   <joint name="left_realsense_joint" type="fixed">
      <pose> -0.023827 0.059696 0.04 0 0 0 </pose>
      <parent link="realsense_housing"/>
      <child link="left_realsense"/>
   </joint>

   <joint name="right_realsense_joint" type="fixed">
      <pose> -0.023827 -0.059696 0.04 0 0 0 </pose>
      <parent link="realsense_housing"/>
      <child link="right_realsense"/>
   </joint>

   <joint name="sonar_joint" type="fixed">
      <pose> 0.0 0.0 0.625 0 0 0 </pose>
      <parent link="stand"/>
      <child link="sonar"/>
   </joint>

   <joint name="pan_servo_joint" type="continuous">
      <pose> -0.03 0.0 0.995 0 0 0 </pose>
      <parent link="stand"/>
      <child link="pan_servo"/>
      <axis>
        <xyz>0 0 1</xyz>
      </axis>
   </joint>

   <joint name="pan_mount_joint" type="fixed">
      <pose> 0.0 0.035 0.01 0 0 0 </pose>
      <parent link="pan_servo"/>
      <child link="pan_tilt_mount"/>
   </joint>

   <joint name="tilt_mount_joint" type="fixed">
      <pose> 0.0 0.016 0.2 0 0 0 </pose>
      <parent link="pan_tilt_mount"/>
      <child link="tilt_servo"/>
   </joint>

   <joint name="tilt_servo_joint" type="continuous">
      <pose> 0.025 -0.016 -0.0525 0 0 0 </pose>
      <parent link="tilt_servo"/>
      <child link="mount"/>
      <axis>
        <xyz>0.0 -1.0 0.0</xyz>
      </axis>
   </joint>

   <joint name="monitor_joint" type="fixed">
      <pose> 0.0725 -0.035 1.9e-05 0 0 0 </pose>
      <parent link="mount"/>
      <child link="monitor"/>
   </joint>

   <joint name="camera_housing_joint" type="fixed">
      <pose> 0.117857 -0.035 0.343649 0 0 0 </pose>
      <parent link="mount"/>
      <child link="camera_housing"/>
   </joint>

   <joint name="camera_joint" type="fixed">
      <pose> 0.024928 8e-06 -0.012136 0 0 0 </pose>
      <parent link="camera_housing"/>
      <child link="camera"/>
   </joint>

   <joint name="caster_joint" type="fixed">
      <pose> 0.2885 0.0 0.03 0 0 0 </pose>
      <parent link="base_link"/>
      <child link="caster"/>
   </joint>


    <plugin name="medibot_diff_drive" filename="libgazebo_ros_diff_drive.so">

      <ros>
        <!-- <namespace>/medibot</namespace> -->
      </ros>

      <update_rate>30</update_rate>

      <!-- wheels -->
      <left_joint>wheel_left_joint</left_joint>
      <right_joint>wheel_right_joint</right_joint>

      <!-- kinematics -->
      <wheel_separation>0.558</wheel_separation>
      <wheel_diameter>0.3</wheel_diameter>

      <!-- limits -->
      <max_wheel_torque>20</max_wheel_torque>
      <max_wheel_acceleration>1.0</max_wheel_acceleration>

      <command_topic>cmd_vel</command_topic>

      <!-- output -->
      <publish_odom>true</publish_odom>
      <publish_odom_tf>true</publish_odom_tf>
      <publish_wheel_tf>false</publish_wheel_tf>

      <odometry_topic>odom</odometry_topic>
      <odometry_frame>odom</odometry_frame>
      <robot_base_frame>base_footprint</robot_base_frame>

    </plugin>

    <plugin name="medibot_joint_state" filename="libgazebo_ros_joint_state_publisher.so">
      <ros>
        <!-- <namespace>/medibot</namespace> -->
        <remapping>~/out:=joint_states</remapping>
      </ros>
      <update_rate>30</update_rate>
      <joint_name>wheel_left_joint</joint_name>
      <joint_name>wheel_right_joint</joint_name>
    </plugin>    

  </model>
</sdf>
